Workbook

Sheet Products
J2: VLookUp
B5: Worksheet 1: Products | F5: Worksheet 2: Orders | M5: 1. Use VLOOKUP to find the product names for each ProductID in the Orders worksheet.
M6: 2. Use VLOOKUP to find the price for each ProductID in the Orders worksheet, then calculate the TotalPrice by multiplying the Quantity by the Product Price.
B7: ProductID | C7: Product | D7: Price | F7: OrderID | G7: ProductID | H7: Quantity | I7: TotalPrice | M7: 3. Use VLOOKUP to check if there are any ProductIDs in the Orders worksheet that do not exist in the Products worksheet.
B8: 101 | C8: PRODUCT A | D8: 120 | F8: 1 | G8: 101 | H8: 2 | M8: 4. Assume a discount of 10% is given on all products. Use VLOOKUP to find the original price and then calculate the discounted price.
B9: 102 | C9: PRODUCT B | D9: 150 | F9: 2 | G9: 103 | H9: 1 | M9: 5. Use VLOOKUP to find the price for each ProductID and then calculate the order value. Find the maximum order value from the list.
B10: 103 | C10: PRODUCT C | D10: 200 | F10: 3 | G10: 105 | H10: 4 | M10: 6. Use VLOOKUP to find out which products from the Products worksheet have not been ordered.
B11: 104 | C11: PRODUCT D | D11: 90 | F11: 4 | G11: 106 | H11: 3 | M11: 7. Use VLOOKUP to find the Product name and summarize the total quantity sold for each product.
B12: 105 | C12: PRODUCT E | D12: 220 | F12: 5 | G12: 102 | H12: 5
B13: 106 | C13: PRODUCT F | D13: 130 | F13: 6 | G13: 104 | H13: 6

Sheet Orders
C4: OrderID | D4: ProductID | E4: Quantity
C5: 1 | D5: 101 | E5: 2
C6: 2 | D6: 103 | E6: 1
C7: 3 | D7: 105 | E7: 4
C8: 4 | D8: 106 | E8: 3
C9: 5 | D9: 102 | E9: 5
C10: 6 | D10: 104 | E10: 6
B11: To Check 3 No.qsn | C11: 7 | D11: 107 | E11: 7
G16: 1. Use VLOOKUP to find the product names for each ProductID in the Orders worksheet.
G18: 1.Product
G19: =VLOOKUP(D5,Products!$B$7:$D$13,2,0) -> PRODUCT A
G20: =VLOOKUP(D6,Products!$B$7:$D$13,2,0) -> PRODUCT C
G21: =VLOOKUP(D7,Products!$B$7:$D$13,2,0) -> PRODUCT E
G22: =VLOOKUP(D8,Products!$B$7:$D$13,2,0) -> PRODUCT F
G23: =VLOOKUP(D9,Products!$B$7:$D$13,2,0) -> PRODUCT B
G24: =VLOOKUP(D10,Products!$B$7:$D$13,2,0) -> PRODUCT D
F25: To Check 3 No.qsn | G25: PRODUCT G
G28: 2. Use VLOOKUP to find the price for each ProductID in the Orders worksheet, then calculate the TotalPrice by multiplying the Quantity by the Product Price.
G30: 2.Price | H30: 2.TotalPrice
G31: =VLOOKUP(D5,Products!$B$7:$D$13,3) -> 120 | H31: =E5*G31 -> 240
G32: =VLOOKUP(D6,Products!$B$7:$D$13,3) -> 200 | H32: =E6*G32 -> 200
G33: =VLOOKUP(D7,Products!$B$7:$D$13,3) -> 220 | H33: =E7*G33 -> 880
G34: =VLOOKUP(D8,Products!$B$7:$D$13,3) -> 130 | H34: =E8*G34 -> 390
G35: =VLOOKUP(D9,Products!$B$7:$D$13,3) -> 150 | H35: =E9*G35 -> 750
G36: =VLOOKUP(D10,Products!$B$7:$D$13,3) -> 90 | H36: =E10*G36 -> 540
G40: 3. Use VLOOKUP to check if there are any ProductIDs in the Orders worksheet that do not exist in the Products worksheet.
G42: 3.Product exists or not
G43: =IF(ISNA(VLOOKUP(D5,Products!$B$7:$D$13,1,0)),"NOT EXIST","EXIST") -> EXIST
G44: =IF(ISNA(VLOOKUP(D6,Products!$B$7:$D$13,1,0)),"NOT EXIST","EXIST") -> EXIST
G45: =IF(ISNA(VLOOKUP(D7,Products!$B$7:$D$13,1,0)),"NOT EXIST","EXIST") -> EXIST
G46: =IF(ISNA(VLOOKUP(D8,Products!$B$7:$D$13,1,0)),"NOT EXIST","EXIST") -> EXIST
G47: =IF(ISNA(VLOOKUP(D9,Products!$B$7:$D$13,1,0)),"NOT EXIST","EXIST") -> EXIST
G48: =IF(ISNA(VLOOKUP(D10,Products!$B$7:$D$13,1,0)),"NOT EXIST","EXIST") -> EXIST
G49: =IF(ISNA(VLOOKUP(D11,Products!$B$7:$D$13,1,0)),"NOT EXIST","EXIST") -> NOT EXIST
G53: 4. Assume a discount of 10% is given on all products. Use VLOOKUP to find the original price and then calculate the discounted price.
G55: 4.Original Price | H55: 4.Discounted Price
G56: =VLOOKUP(D5,Products!$B$7:$D$13,3) -> 120 | H56: =G56*0.9 -> 108
G57: =VLOOKUP(D6,Products!$B$7:$D$13,3) -> 200 | H57: =G57*0.9 -> 180
G58: =VLOOKUP(D7,Products!$B$7:$D$13,3) -> 220 | H58: =G58*0.9 -> 198
G59: =VLOOKUP(D8,Products!$B$7:$D$13,3) -> 130 | H59: =G59*0.9 -> 117
...
